Workbook

Sheet  Leave Record - IT
A1: No | B1: Name of Staff | C1: DOJ | D1: Employee Code | E1: Leave | F1: Total | G1: Leave Availed | H1: No | I1: C_Month | J1: C_No | K1: Sick | L1: No | M1: Casual | N1: No | O1: Comp_off | P1: No
A2: 1 | B2: Chandrashekar | C2: 39539 | D2: CNS354 | E2: 2024 | F2: 24 | G2: 01Apr - 11Apr | H2: 8 | I2: Apr | J2: 8 | K2: 45708 | L2: 1 | M2: 45670 | N2: 1
B3: Padashetty | E3: 2025 | F3: 21 | G3: 03Sept - 09Sept | H3: 4 | I3: May | K3: 45799 | L3: 1 | M3: 45671 | N3: 1
G4: 18NOv - 20Nov | H4: 3 | I4: Jun | K4: 45862 | L4: 1 | M4: 45817 | N4: 1
G5: 02Dec - 05Dec | H5: 4 | I5: Jul | K5: 45929 | L5: 1 | M5: 45818 | N5: 1
G6: 22Dec - 23Dec | H6: 2 | I6: Aug | K6: 45936 | L6: 0.5 | M6: 45880 | N6: 1
I7: Sep | J7: 4 | K7: 45954 | L7: 1 | M7: 45881 | N7: 1
I8: Oct | K8: 45959 | L8: 1 | M8: 45919 | N8: 1
I9: Nov | J9: 3 | K9: 45960 | L9: 1 | M9: 46000 | N9: 1
I10: Dec | J10: 6 | K10: 45972 | L10: 1 | M10: 46001 | N10: 1
I11: Jan | K11: 46003 | L11: 1
I12: Feb | K12: 46021 | L12: 0.5
I13: Mar
F14: =SUM(F2:F12) -> 45 | H14: =SUM(H2:H12) -> 21 | J14: =SUM(J2:J13) -> 21 | L14: =SUM(L2:L12) -> 10 | N14: =SUM(N2:N12) -> 9 | P14: =SUM(P2:P12) -> 0
B15: Leave Balance | H15: =SUM(F14-H14) -> 24 | L15: =SUM(10-L14) -> 0 | N15: =SUM(10-N14) -> 1
A18: 2 | B18: Abhijit Bhandal | C18: 39778 | D18: CNS395 | E18: 2024 | F18: 24 | G18: 10Feb - 14Feb | H18: 5 | I18: Apr | K18: 45748 | L18: 1 | M18: 45758 | N18: 1
E19: 2025 | F19: 21 | G19: 21Aug - 04Sep | H19: 10 | I19: May | K19: 45803 | L19: 1 | M19: 45782 | N19: 1
G20: 09Oct - 13Oct | H20: 3 | I20: Jun | K20: 45841 | L20: 1 | M20: 45783 | N20: 1
G21: 29Dec - 31Dec | H21: 3 | I21: Jul | K21: 45912 | L21: 1 | M21: 45918 | N21: 1
I22: Aug | J22: 7 | K22: 45926 | L22: 1 | M22: 45919 | N22: 1
I23: Sep | J23: 4 | K23: 45959 | L23: 1 | M23: 45950 | N23: 1
I24: Oct | J24: 3 | K24: 45960 | L24: 1 | M24: 45954 | N24: 1
I25: Nov | K25: 45979 | L25: 1 | M25: 45989 | N25: 1
I26: Dec | J26: 3 | K26: 45980 | L26: 1 | M26: 45992 | N26: 1
I27: Jan | K27: 45981 | L27: 1 | M27: 45993 | N27: 1
I28: Feb
I29: Mar
F30: =SUM(F18:F27) -> 45 | H30: =SUM(H18:H27) -> 21 | J30: =SUM(J18:J29) -> 17 | L30: =SUM(L18:L27) -> 10 | N30: =SUM(N18:N27) -> 10 | P30: =SUM(P18:P27) -> 0
B31: Leave Balance | H31: =SUM(F30-H30) -> 24 | L31: =SUM(10-L30) -> 0 | N31: =SUM(10-N30) -> 0
A34: 3 | B34: Santosh Kamath | C34: 41683 | D34: CNS741 | E34: 2024 | F34: 23 | G34: 17Feb - 21Feb | H34: 5 | I34: Apr | K34: 45776 | L34: 1 | M34: 45814 | N34: 1
E35: 2025 | F35: 21 | G35: 08Oct - 10Oct | H35: 3 | I35: May | K35: 45798 | L35: 1 | M35: 45828 | N35: 1
G36: 29Oct - 31Oct | H36: 3 | I36: Jun | K36: 45799 | L36: 1 | M36: 45848 | N36: 1
G37: 45967 | H37: 1 | I37: Jul | K37: 45866 | L37: 1 | M37: 45852 | N37: 1
G38: 10Nov - 11Nov | H38: 2 | I38: Aug | K38: 45867 | L38: 1 | M38: 45908 | N38: 1
G39: 45993 | H39: 1 | I39: Sep | K39: 45868 | L39: 1 | M39: 45912 | N39: 1
G40: 15Dec - 19Dec | H40: 5 | I40: Oct | J40: 6 | K40: 45929 | L40: 1 | M40: 45980 | N40: 1
I41: Nov | J41: 3 | K41: 45950 | L41: 1 | M41: 45981 | N41: 1
I42: Dec | J42: 6 | K42: 45995 | L42: 1 | M42: 46021 | N42: 1
I43: Jan | K43: 45996 | L43: 1 | M43: 46022 | N43: 1
I44: Feb
...

Sheet Leave Record_FY24-25
B2: Department Name | C2: IT TEAM
B4: APR 2024 - MAR 2025
B6: Employee Code | C6: Names of the Staff | D6: Leave Balance as on 31.03.24 | E6: Add :01.04.24 to 31.03.25 | F6: Total as on 31.03.25 | G6: Less : PL Taken 01.04.24 to 31.03.25 | H6: Closing Balance as on 31.03.25
B10: CNS116 | C10: Rajesh Kotian | D10: 21 | E10: 21 | F10: =D10+E10 -> 42 | G10: 16 | H10: =F10-G10 -> 26
B12: CNS354 | C12: Chandrashekar P | D12: 16 | E12: 21 | F12: =D12+E12 -> 37 | G12: =' Leave Record - IT'!J14 -> 21 | H12: =F12-G12 -> 16
B14: CNS395 | C14: Abhijit Bandal | D14: 20 | E14: 21 | F14: =D14+E14 -> 41 | G14: =' Leave Record - IT'!J30 -> 17 | H14: =F14-G14 -> 24
B16: CNS741 | C16: Santosh Kamath | D16: 22 | E16: 21 | F16: =D16+E16 -> 43 | G16: =' Leave Record - IT'!J46 -> 15 | H16: =F16-G16 -> 28
B18: CNS1006 | C18: Lokesh Poojary | D18: 9 | E18: 21 | F18: =D18+E18 -> 30 | G18: =' Leave Record - IT'!J62 -> 10 | H18: =F18-G18 -> 20
B20: CNS1284 | C20: Pravin Walam | D20: 0 | E20: 5 | F20: =D20+E20 -> 5 | G20: =' Leave Record - IT'!J78 -> 6 | H20: =F20-G20 -> -1
