Workbook

Sheet Sheet1
A1: Sr. No. | B1: User Name | C1: Cathay ID | D1: Email Address | E1: DEPT | F1: CRC_completion | G1: CRC_Expire | H1: CRC_Recert | I1: PPL_completion | J1: PPL_Expire | K1: PPL_Recert
A2: 1 | B2: A Ramesh | C2: V027ARM | D2: V027ARM@cathaypacific.com | E2: FLTB_PRT | F2: 45993 | G2: =IFERROR(IF(Sheet1!$F2="","",Sheet1!$F2+365),"") -> 46358 | H2: =IFERROR(IF(Sheet1!$F2="","",Sheet1!$F2+335),"") -> 46328 | I2: 45961 | J2: =IFERROR(IF(Sheet1!$I2="","",Sheet1!$I2+365),"") -> 46326 | K2: =IFERROR(IF(Sheet1!$I2="","",Sheet1!$I2+305),"") -> 46266
A3: 2 | B3: Aafiya Siddiqui | C3: V027AAA | D3: V027AAA@cathaypacific.com | E3: FOP_NCT | F3: 46116 | G3: =IFERROR(IF(Sheet1!$F3="","",Sheet1!$F3+365),"") -> 46481 | H3: =IFERROR(IF(Sheet1!$F3="","",Sheet1!$F3+335),"") -> 46451 | I3: 46116 | J3: =IFERROR(IF(Sheet1!$I3="","",Sheet1!$I3+365),"") -> 46481 | K3: =IFERROR(IF(Sheet1!$I3="","",Sheet1!$I3+305),"") -> 46421
A4: 3 | B4: Aarti Sehgal | C4: CPPAARS | D4: aarti_sehgal@cathaypacific.com | E4: SSR | F4: 45998 | G4: =IFERROR(IF(Sheet1!$F4="","",Sheet1!$F4+365),"") -> 46363 | H4: =IFERROR(IF(Sheet1!$F4="","",Sheet1!$F4+335),"") -> 46333 | I4: 45992 | J4: =IFERROR(IF(Sheet1!$I4="","",Sheet1!$I4+365),"") -> 46357 | K4: =IFERROR(IF(Sheet1!$I4="","",Sheet1!$I4+305),"") -> 46297
A5: 4 | B5: Aashna Momin | C5: V027AAS | D5: V027AAS@cathaypacific.com | E5: DCQ | F5: 45982 | G5: =IFERROR(IF(Sheet1!$F5="","",Sheet1!$F5+365),"") -> 46347 | H5: =IFERROR(IF(Sheet1!$F5="","",Sheet1!$F5+335),"") -> 46317 | I5: 45918 | J5: =IFERROR(IF(Sheet1!$I5="","",Sheet1!$I5+365),"") -> 46283 | K5: =IFERROR(IF(Sheet1!$I5="","",Sheet1!$I5+305),"") -> 46223
A6: 5 | B6: Abdul Rahman Khan | C6: V027AKT | D6: V027AKT@cathaypacific.com | E6: FLTB_PRT | F6: 45988 | G6: =IFERROR(IF(Sheet1!$F6="","",Sheet1!$F6+365),"") -> 46353 | H6: =IFERROR(IF(Sheet1!$F6="","",Sheet1!$F6+335),"") -> 46323 | I6: 45938 | J6: =IFERROR(IF(Sheet1!$I6="","",Sheet1!$I6+365),"") -> 46303 | K6: =IFERROR(IF(Sheet1!$I6="","",Sheet1!$I6+305),"") -> 46243
A7: 6 | B7: Abhijit Bandal | C7: CPPABB | D7: abhijit_bandal@cathaypacific.com | E7: IT | F7: 46001 | G7: =IFERROR(IF(Sheet1!$F7="","",Sheet1!$F7+365),"") -> 46366 | H7: =IFERROR(IF(Sheet1!$F7="","",Sheet1!$F7+335),"") -> 46336 | I7: 45999 | J7: =IFERROR(IF(Sheet1!$I7="","",Sheet1!$I7+365),"") -> 46364 | K7: =IFERROR(IF(Sheet1!$I7="","",Sheet1!$I7+305),"") -> 46304
A8: 7 | B8: Abhijit Khule | C8: CPPKHUA | D8: abhijit_khule@cathaypacific.com | E8: FARES | F8: 45997 | G8: =IFERROR(IF(Sheet1!$F8="","",Sheet1!$F8+365),"") -> 46362 | H8: =IFERROR(IF(Sheet1!$F8="","",Sheet1!$F8+335),"") -> 46332 | I8: 45940 | J8: =IFERROR(IF(Sheet1!$I8="","",Sheet1!$I8+365),"") -> 46305 | K8: =IFERROR(IF(Sheet1!$I8="","",Sheet1!$I8+305),"") -> 46245
A9: 8 | B9: Abhinay Ahire | C9: CPPAAH | D9: abhinay_ahire@cathaypacific.com | E9: FARES | F9: 45979 | G9: =IFERROR(IF(Sheet1!$F9="","",Sheet1!$F9+365),"") -> 46344 | H9: =IFERROR(IF(Sheet1!$F9="","",Sheet1!$F9+335),"") -> 46314 | I9: 45947 | J9: =IFERROR(IF(Sheet1!$I9="","",Sheet1!$I9+365),"") -> 46312 | K9: =IFERROR(IF(Sheet1!$I9="","",Sheet1!$I9+305),"") -> 46252
A10: 9 | B10: Ajinkya Lepkar | C10: V027AJL | D10: V027AJL@cathaypacific.com | E10: FARES | F10: 45881 | G10: =IFERROR(IF(Sheet1!$F10="","",Sheet1!$F10+365),"") -> 46246 | H10: =IFERROR(IF(Sheet1!$F10="","",Sheet1!$F10+335),"") -> 46216 | I10: 45880 | J10: =IFERROR(IF(Sheet1!$I10="","",Sheet1!$I10+365),"") -> 46245 | K10: =IFERROR(IF(Sheet1!$I10="","",Sheet1!$I10+305),"") -> 46185
A11: 10 | B11: Ajit Babar | C11: CPPAJBR | D11: ajit_babar@cathaypacific.com | E11: FLTB_PRT | F11: 45980 | G11: =IFERROR(IF(Sheet1!$F11="","",Sheet1!$F11+365),"") -> 46345 | H11: =IFERROR(IF(Sheet1!$F11="","",Sheet1!$F11+335),"") -> 46315 | I11: 45932 | J11: =IFERROR(IF(Sheet1!$I11="","",Sheet1!$I11+365),"") -> 46297 | K11: =IFERROR(IF(Sheet1!$I11="","",Sheet1!$I11+305),"") -> 46237
A12: 11 | B12: Akbar Ahmed Hashmi | C12: V027AHA | D12: V027AHA@cathaypacific.com | E12: FARES | F12: 45814 | G12: =IFERROR(IF(Sheet1!$F12="","",Sheet1!$F12+365),"") -> 46179 | H12: =IFERROR(IF(Sheet1!$F12="","",Sheet1!$F12+335),"") -> 46149 | I12: 45806 | J12: =IFERROR(IF(Sheet1!$I12="","",Sheet1!$I12+365),"") -> 46171 | K12: =IFERROR(IF(Sheet1!$I12="","",Sheet1!$I12+305),"") -> 46111
A13: 12 | B13: Akshay Poojari | C13: V027AKP | D13: V027AKP@cathaypacific.com | E13: FARES | F13: 45880 | G13: =IFERROR(IF(Sheet1!$F13="","",Sheet1!$F13+365),"") -> 46245 | H13: =IFERROR(IF(Sheet1!$F13="","",Sheet1!$F13+335),"") -> 46215 | I13: 45880 | J13: =IFERROR(IF(Sheet1!$I13="","",Sheet1!$I13+365),"") -> 46245 | K13: =IFERROR(IF(Sheet1!$I13="","",Sheet1!$I13+305),"") -> 46185
... A50: 49 | B50: Chetan Bavakar | C50: CPPCHBA | D50: chetan_bavakar@cathaypacific.com | E50: FLTB_PRT | F50: 45978 | G50: =IFERROR(IF(Sheet1!$F50="","",Sheet1!$F50+365),"") -> 46343 | H50: =IFERROR(IF(Sheet1!$F50="","",Sheet1!$F50+335),"") -> 46313 | I50: 45918 | J50: =IFERROR(IF(Sheet1!$I50="","",Sheet1!$I50+365),"") -> 46283 | K50: =IFERROR(IF(Sheet1!$I50="","",Sheet1!$I50+305),"") -> 46223
A51: 50 | B51: Clare Noronha | C51: CPPCLN | D51: clare_noronha@cathaypacific.com | E51: OPS | G51: =IFERROR(IF(Sheet1!$F51="","",Sheet1!$F51+365),"") | H51: =IFERROR(IF(Sheet1!$F51="","",Sheet1!$F51+335),"") | J51: =IFERROR(IF(Sheet1!$I51="","",Sheet1!$I51+365),"") | K51: =IFERROR(IF(Sheet1!$I51="","",Sheet1!$I51+305),"")
A52: 51 | B52: Clevita Leitao | C52: V027CLL | D52: v027cll@cathaypacific.com | E52: HtR | F52: 45805 | G52: =IFERROR(IF(Sheet1!$F52="","",Sheet1!$F52+365),"") -> 46170 | H52: =IFERROR(IF(Sheet1!$F52="","",Sheet1!$F52+335),"") -> 46140 | I52: 45803 | J52: =IFERROR(IF(Sheet1!$I52="","",Sheet1!$I52+365),"") -> 46168 | K52: =IFERROR(IF(Sheet1!$I52="","",Sheet1!$I52+305),"") -> 46108
A53: 52 | B53: Daksha Deveriya | C53: V027DDD | D53: v027ddd@cathaypacific.com | E53: HtR | F53: 45995 | G53: =IFERROR(IF(Sheet1!$F53="","",Sheet1!$F53+365),"") -> 46360 | H53: =IFERROR(IF(Sheet1!$F53="","",Sheet1!$F53+335),"") -> 46330 | I53: 45966 | J53: =IFERROR(IF(Sheet1!$I53="","",Sheet1!$I53+365),"") -> 46331 | K53: =IFERROR(IF(Sheet1!$I53="","",Sheet1!$I53+305),"") -> 46271
A54: 53 | B54: Darshan Satra | C54: V027BDS | D54: V027BDS@cathaypacific.com | E54: FLTB_PRT | F54: 46002 | G54: =IFERROR(IF(Sheet1!$F54="","",Sheet1!$F54+365),"") -> 46367 | H54: =IFERROR(IF(Sheet1!$F54="","",Sheet1!$F54+335),"") -> 46337 | I54: 45973 | J54: =IFERROR(IF(Sheet1!$I54="","",Sheet1!$I54+365),"") -> 46338 | K54: =IFERROR(IF(Sheet1!$I54="","",Sheet1!$I54+305),"") -> 46278
A55: 54 | B55: Darshana Chunekar | C55: CPPDHC | D55: darshana_chunekar@cathaypacific.com | E55: FARES | F55: 45985 | G55: =IFERROR(IF(Sheet1!$F55="","",Sheet1!$F55+365),"") -> 46350 | H55: =IFERROR(IF(Sheet1!$F55="","",Sheet1!$F55+335),"") -> 46320 | I55: 45970 | J55: =IFERROR(IF(Sheet1!$I55="","",Sheet1!$I55+365),"") -> 46335 | K55: =IFERROR(IF(Sheet1!$I55="","",Sheet1!$I55+305),"") -> 46275
A56: 55 | B56: Darshana Keni | C56: CPPDAK | D56: darshana_keni@cathaypacific.com | E56: FLTB_PRT | F56: 45988 | G56: =IFERROR(IF(Sheet1!$F56="","",Sheet1!$F56+365),"") -> 46353 | H56: =IFERROR(IF(Sheet1!$F56="","",Sheet1!$F56+335),"") -> 46323 | I56: 45932 | J56: =IFERROR(IF(Sheet1!$I56="","",Sheet1!$I56+365),"") -> 46297 | K56: =IFERROR(IF(Sheet1!$I56="","",Sheet1!$I56+305),"") -> 46237
A57: 56 | B57: Deborah Narayanan | C57: CPPDEN | D57: deborah_narayanan@cathaypacific.com | E57: FARES | F57: 45992 | G57: =IFERROR(IF(Sheet1!$F57="","",Sheet1!$F57+365),"") -> 46357 | H57: =IFERROR(IF(Sheet1!$F57="","",Sheet1!$F57+335),"") -> 46327 | I57: 45975 | J57: =IFERROR(IF(Sheet1!$I57="","",Sheet1!$I57+365),"") -> 46340 | K57: =IFERROR(IF(Sheet1!$I57="","",Sheet1!$I57+305),"") -> 46280
A58: 57 | B58: Deepak Gaikwad | C58: V027DDG | D58: V027DDG@cathaypacific.com | E58: SSR | F58: 45992 | G58: =IFERROR(IF(Sheet1!$F58="","",Sheet1!$F58+365),"") -> 46357 | H58: =IFERROR(IF(Sheet1!$F58="","",Sheet1!$F58+335),"") -> 46327 | I58: 45905 | J58: =IFERROR(IF(Sheet1!$I58="","",Sheet1!$I58+365),"") -> 46270 | K58: =IFERROR(IF(Sheet1!$I58="","",Sheet1!$I58+305),"") -> 46210
A59: 58 | B59: Deepak Pawar | C59: CPPDPAK | D59: deepak_pawar@cathaypacific.com | E59: FARES | F59: 45997 | G59: =IFERROR(IF(Sheet1!$F59="","",Sheet1!$F59+365),"") -> 46362 | H59: =IFERROR(IF(Sheet1!$F59="","",Sheet1!$F59+335),"") -> 46332 | I59: 45952 | J59: =IFERROR(IF(Sheet1!$I59="","",Sheet1!$I59+365),"") -> 46317 | K59: =IFERROR(IF(Sheet1!$I59="","",Sheet1!$I59+305),"") -> 46257
A60: 59 | B60: Deepak Rajguru | C60: CPPDKRU | D60: deepak_rajguru@cathaypacific.com | E60: SSR | F60: 45998 | G60: =IFERROR(IF(Sheet1!$F60="","",Sheet1!$F60+365),"") -> 46363 | H60: =IFERROR(IF(Sheet1!$F60="","",Sheet1!$F60+335),"") -> 46333 | I60: 45943 | J60: =IFERROR(IF(Sheet1!$I60="","",Sheet1!$I60+365),"") -> 46308 | K60: =IFERROR(IF(Sheet1!$I60="","",Sheet1!$I60+305),"") -> 46248
A61: 60 | B61: Deepak Rawat | C61: V027DER | D61: V027DER@cathaypacific.com | E61: FARES | F61: 45960 | G61: =IFERROR(IF(Sheet1!$F61="","",Sheet1!$F61+365),"") -> 46325 | H61: =IFERROR(IF(Sheet1!$F61="","",Sheet1!$F61+335),"") -> 46295 | I61: 45960 | J61: =IFERROR(IF(Sheet1!$I61="","",Sheet1!$I61+365),"") -> 46325 | K61: =IFERROR(IF(Sheet1!$I61="","",Sheet1!$I61+305),"") -> 46265
A62: 61 | B62: Deepika Mayangade | C62: CPPDEEM | D62: deepika_mayangade@cathaypacific.com | E62: FARES | F62: 45997 | G62: =IFERROR(IF(Sheet1!$F62="","",Sheet1!$F62+365),"") -> 46362 | H62: =IFERROR(IF(Sheet1!$F62="","",Sheet1!$F62+335),"") -> 46332 | I62: 45967 | J62: =IFERROR(IF(Sheet1!$I62="","",Sheet1!$I62+365),"") -> 46332 | K62: =IFERROR(IF(Sheet1!$I62="","",Sheet1!$I62+305),"") -> 46272
A63: 62 | B63: Deepti Muranjan | C63: CPPDEM | D63: deepti_muranjan@cathaypacific.com | E63: FLTB_PRT | F63: 45978 | G63: =IFERROR(IF(Sheet1!$F63="","",Sheet1!$F63+365),"") -> 46343 | H63: =IFERROR(IF(Sheet1!$F63="","",Sheet1!$F63+335),"") -> 46313 | I63: 45911 | J63: =IFERROR(IF(Sheet1!$I63="","",Sheet1!$I63+365),"") -> 46276 | K63: =IFERROR(IF(Sheet1!$I63="","",Sheet1!$I63+305),"") -> 46216
... A72: 71 | B72: Durgesh Singh | C72: V027DUS | D72: v027dus@cathaypacific.com | E72: FOP_NCT | F72: 45982 | G72: =IFERROR(IF(Sheet1!$F72="","",Sheet1!$F72+365),"") -> 46347 | H72: =IFERROR(IF(Sheet1!$F72="","",Sheet1!$F72+335),"") -> 46317 | I72: 45982 | J72: =IFERROR(IF(Sheet1!$I72="","",Sheet1!$I72+365),"") -> 46347 | K72: =IFERROR(IF(Sheet1!$I72="","",Sheet1!$I72+305),"") -> 46287
A73: 72 | B73: Dusa Sangthong | C73: CPPDUS | D73: dusa_sangthong@cathaypacific.com | E73: OPS | G73: =IFERROR(IF(Sheet1!$F73="","",Sheet1!$F73+365),"") | H73: =IFERROR(IF(Sheet1!$F73="","",Sheet1!$F73+335),"") | J73: =IFERROR(IF(Sheet1!$I73="","",Sheet1!$I73+365),"") | K73: =IFERROR(IF(Sheet1!$I73="","",Sheet1!$I73+305),"")
A74: 73 | B74: Ellery Mendonsa | C74: CPPELLM | D74: ellery_mendonsa@cathaypacific.com | E74: SSR | F74: 45996 | G74: =IFERROR(IF(Sheet1!$F74="","",Sheet1!$F74+365),"") -> 46361 | H74: =IFERROR(IF(Sheet1!$F74="","",Sheet1!$F74+335),"") -> 46331 | I74: 45911 | J74: =IFERROR(IF(Sheet1!$I74="","",Sheet1!$I74+365),"") -> 46276 | K74: =IFERROR(IF(Sheet1!$I74="","",Sheet1!$I74+305),"") -> 46216
A75: 74 | B75: Elsa D'Costa | C75: CPPELD | D75: elsa_dcosta@cathaypacific.com | E75: PA | G75: =IFERROR(IF(Sheet1!$F75="","",Sheet1!$F75+365),"") | H75: =IFERROR(IF(Sheet1!$F75="","",Sheet1!$F75+335),"") | J75: =IFERROR(IF(Sheet1!$I75="","",Sheet1!$I75+365),"") | K75: =IFERROR(IF(Sheet1!$I75="","",Sheet1!$I75+305),"")
A76: 75 | B76: Faizan Motiwala | C76: V027FFM | D76: v027ffm@cathaypacific.com | E76: FLTB_PRT | F76: 45979 | G76: =IFERROR(IF(Sheet1!$F76="","",Sheet1!$F76+365),"") -> 46344 | H76: =IFERROR(IF(Sheet1!$F76="","",Sheet1!$F76+335),"") -> 46314 | I76: 45910 | J76: =IFERROR(IF(Sheet1!$I76="","",Sheet1!$I76+365),"") -> 46275 | K76: =IFERROR(IF(Sheet1!$I76="","",Sheet1!$I76+305),"") -> 46215
A77: 76 | B77: Faizan Shaikh | C77: V027FAS | D77: V027FAS@cathaypacific.com | E77: FOP_NCT | F77: 45803 | G77: =IFERROR(IF(Sheet1!$F77="","",Sheet1!$F77+365),"") -> 46168 | H77: =IFERROR(IF(Sheet1!$F77="","",Sheet1!$F77+335),"") -> 46138 | I77: 45803 | J77: =IFERROR(IF(Sheet1!$I77="","",Sheet1!$I77+365),"") -> 46168 | K77: =IFERROR(IF(Sheet1!$I77="","",Sheet1!$I77+305),"") -> 46108
A78: 77 | B78: Flavina Fernandes | C78: V027FFF | D78: flavina_fernandes@cathaypacific.com | E78: IET | F78: 45993 | G78: =IFERROR(IF(Sheet1!$F78="","",Sheet1!$F78+365),"") -> 46358 | H78: =IFERROR(IF(Sheet1!$F78="","",Sheet1!$F78+335),"") -> 46328 | I78: 45939 | J78: =IFERROR(IF(Sheet1!$I78="","",Sheet1!$I78+365),"") -> 46304 | K78: =IFERROR(IF(Sheet1!$I78="","",Sheet1!$I78+305),"") -> 46244
A79: 78 | B79: Gayas Sait | C79: V027GAS | D79: V027GAS@cathaypacific.com | E79: FARES | F79: 45957 | G79: =IFERROR(IF(Sheet1!$F79="","",Sheet1!$F79+365),"") -> 46322 | H79: =IFERROR(IF(Sheet1!$F79="","",Sheet1!$F79+335),"") -> 46292 | I79: 45957 | J79: =IFERROR(IF(Sheet1!$I79="","",Sheet1!$I79+365),"") -> 46322 | K79: =IFERROR(IF(Sheet1!$I79="","",Sheet1!$I79+305),"") -> 46262
A80: 79 | B80: Harsha Salekar | C80: V027HHS | D80: V027HHS@cathaypacific.com | E80: SSR | F80: 45948 | G80: =IFERROR(IF(Sheet1!$F80="","",Sheet1!$F80+365),"") -> 46313 | H80: =IFERROR(IF(Sheet1!$F80="","",Sheet1!$F80+335),"") -> 46283 | I80: 45954 | J80: =IFERROR(IF(Sheet1!$I80="","",Sheet1!$I80+365),"") -> 46319 | K80: =IFERROR(IF(Sheet1!$I80="","",Sheet1!$I80+305),"") -> 46259
A81: 80 | B81: Harshada Ghate | C81: V027HHG | D81: harshada_ghate@cathaypacific.com | E81: IET | F81: 45981 | G81: =IFERROR(IF(Sheet1!$F81="","",Sheet1!$F81+365),"") -> 46346 | H81: =IFERROR(IF(Sheet1!$F81="","",Sheet1!$F81+335),"") -> 46316 | I81: 45974 | J81: =IFERROR(IF(Sheet1!$I81="","",Sheet1!$I81+365),"") -> 46339 | K81: =IFERROR(IF(Sheet1!$I81="","",Sheet1!$I81+305),"") -> 46279
A82: 81 | B82: Harshal Karande | C82: V027HHK | D82: v027hhk@cathaypacific.com | E82: FOP_NCT | F82: 45983 | G82: =IFERROR(IF(Sheet1!$F82="","",Sheet1!$F82+365),"") -> 46348 | H82: =IFERROR(IF(Sheet1!$F82="","",Sheet1!$F82+335),"") -> 46318 | I82: 45979 | J82: =IFERROR(IF(Sheet1!$I82="","",Sheet1!$I82+365),"") -> 46344 | K82: =IFERROR(IF(Sheet1!$I82="","",Sheet1!$I82+305),"") -> 46284
A83: 82 | B83: Harvey De Souza | C83: V027HDS | D83: v027hds@cathaypacific.com | E83: DWNL | F83: 45978 | G83: =IFERROR(IF(Sheet1!$F83="","",Sheet1!$F83+365),"") -> 46343 | H83: =IFERROR(IF(Sheet1!$F83="","",Sheet1!$F83+335),"") -> 46313 | I83: 45987 | J83: =IFERROR(IF(Sheet1!$I83="","",Sheet1!$I83+365),"") -> 46352 | K83: =IFERROR(IF(Sheet1!$I83="","",Sheet1!$I83+305),"") -> 46292
A84: 83 | B84: Himanshu Shardule | C84: CPPHUSE | D84: himanshu_shardule@cathaypacific.com | E84: FLTB_PRT | F84: 45979 | G84: =IFERROR(IF(Sheet1!$F84="","",Sheet1!$F84+365),"") -> 46344 | H84: =IFERROR(IF(Sheet1!$F84="","",Sheet1!$F84+335),"") -> 46314 | I84: 45910 | J84: =IFERROR(IF(Sheet1!$I84="","",Sheet1!$I84+365),"") -> 46275 | K84: =IFERROR(IF(Sheet1!$I84="","",Sheet1!$I84+305),"") -> 46215
...
